Workbook
Name pic: INDEX([1]!Table1[รูปภาพ],MATCH(#REF!,[1]!Table1[สินค้า],0))

Sheet Setup picture
B2: ເຂື່ອນ | C2: ຮູບພາບ
B3: (All) | C3: #VALUE!
B4: NEM | C4: #VALUE!
B5: NK2 | C5: #VALUE!
B6: NK3 | C6: #VALUE!
B7: NNG3A | C7: #VALUE!
B8: XNN1 | C8: #VALUE!
B9: NSPC | C9: #VALUE!

Sheet DATA
B1: NEM | Q1: NK3 | AF1: NK2 | AU1: NNG3A | BI1: XNN1 | BW1: NSPC (NamPhak+NamPha Reservoir (US)) | CL1: NSPC (PhouPong Reservoir (DS))
A2: ວັນທີ | B2: ປະລິມານ ນໍ້າຝົນ (mm) | C2: ແຜນນໍ້າເຂົ້າ (MCM) | D2: ນໍ້າເຂົ້າ (MCM) | E2: ນໍ້າອອກTB discharge (MCM) | F2: ນໍ້າລົ້ນ Overflow (MCM) | G2: ບໍລິມາດນໍ້າໃນອ່າງ (MCM) | H2: % ນໍ້າໃນອ່າງ | I2: ນໍ້າໃຊ້ໄດ້ (MCM) | J2: % ນໍ້າໃຊ້ໄດ້ | K2: ລະດັບນໍ້າ ສູງສຸດ MASL | L2: ລະດັບນໍ້າ ຕໍ່າສຸດ MASL | M2: ລະດັບນໍ້າຈີງ ເຂື່ອນຫຼັກ MASL | N2: ລະດັບນໍ້າຈີງ ເຂື່ອນອ່ວຍນໍ້າ MASL | O2: ແຜນພະລັງງານ (GWh) | P2: ພະລັງງານຈີງ (GWh) | Q2: ປະລິມານ ນໍ້າຝົນ (mm) | R2: ແຜນນໍ້າເຂົ້າ (MCM) | S2: ນໍ້າເຂົ້າ (MCM) | T2: ນໍ້າອອກTB discharge (MCM) | U2: ນໍ້າລົ້ນ Overflow (MCM) | V2: ບໍລິມາດນໍ້າໃນອ່າງ (MCM) | W2: % ນໍ້າໃນອ່າງ | X2: ນໍ້າໃຊ້ໄດ້ (MCM) | Y2: % ນໍ້າໃຊ້ໄດ້ | Z2: ລະດັບນໍ້າ ສູງສຸດ MASL | AA2: ລະດັບນໍ້າ ຕໍ່າສຸດ MASL | AB2: Plan WL masl | AC2: ລະດັບນໍ້າຈີງ MASL | AD2: ແຜນພະລັງງານ (GWh) | AE2: ພະລັງງານຈີງ (GWh) | AF2: ປະລິມານ ນໍ້າຝົນ (mm) | AG2: ແຜນນໍ້າເຂົ້າ (MCM) | AH2: ນໍ້າເຂົ້າ (MCM) | AI2: ນໍ້າອອກTB discharge (MCM) | AJ2: ນໍ້າລົ້ນ Overflow (MCM) | AK2: ບໍລິມາດນໍ້າໃນອ່າງ (MCM) | AL2: % ນໍ້າໃນອ່າງ | AM2: ນໍ້າໃຊ້ໄດ້ (MCM) | AN2: % ນໍ້າໃຊ້ໄດ້ | AO2: ລະດັບນໍ້າ ສູງສຸດ MASL | AP2: ລະດັບນໍ້າ ຕໍ່າສຸດ MASL | AQ2: Plan WL masl | AR2: ລະດັບນໍ້າຈີງ MASL | AS2: ແຜນພະລັງງານ (GWh) | AT2: ພະລັງງານຈີງ (GWh) | AU2: ປະລິມານ ນໍ້າຝົນ (mm) | AV2: ແຜນນໍ້າເຂົ້າ (MCM) | AW2: ນໍ້າເຂົ້າ (MCM) | AX2: ນໍ້າອອກTB discharge (MCM) | AY2: ນໍ້າລົ້ນ Overflow (MCM) | AZ2: ບໍລິມາດນໍ້າໃນອ່າງ (MCM) | BA2: % ນໍ້າໃນອ່າງ | BB2: ນໍ້າໃຊ້ໄດ້ (MCM) | BC2: % ນໍ້າໃຊ້ໄດ້ | BD2: ລະດັບນໍ້າ ສູງສຸດ MASL | BE2: ລະດັບນໍ້າ ຕໍ່າສຸດ MASL | BF2: ລະດັບນໍ້າຈີງ MASL | BG2: ແຜນພະລັງງານ (GWh) | BH2: ພະລັງງານຈີງ (GWh) | BI2: ປະລິມານ ນໍ້າຝົນ (mm) | BJ2: ແຜນນໍ້າເຂົ້າ (MCM) | BK2: ນໍ້າເຂົ້າ (MCM) | BL2: ນໍ້າອອກTB discharge (MCM) | BM2: ນໍ້າລົ້ນ Overflow (MCM) | BN2: ບໍລິມາດນໍ້າໃນອ່າງ (MCM) | BO2: % ນໍ້າໃນອ່າງ | BP2: ນໍ້າໃຊ້ໄດ້ (MCM) | BQ2: % ນໍ້າໃຊ້ໄດ້ | BR2: ລະດັບນໍ້າ ສູງສຸດ MASL | BS2: ລະດັບນໍ້າ ຕໍ່າສຸດ MASL | BT2: ລະດັບນໍ້າຈີງ MASL | BU2: ແຜນພະລັງງານ (GWh) | BV2: ພະລັງງານຈີງ (GWh) | BW2: ປະລິມານ ນໍ້າຝົນ (mm) | BX2: ແຜນນໍ້າເຂົ້າ (MCM) | BY2: ນໍ້າເຂົ້າ (MCM) | BZ2: ນໍ້າອອກTB discharge (MCM) | CA2: ນໍ້າລົ້ນ Overflow (MCM) | CB2: ບໍລິມາດນໍ້າໃນອ່າງ (MCM) | CC2: % ນໍ້າໃນອ່າງ | CD2: ນໍ້າໃຊ້ໄດ້ (MCM) | CE2: % ນໍ້າໃຊ້ໄດ້ | CF2: ລະດັບນໍ້າ ສູງສຸດ MASL | CG2: ລະດັບນໍ້າ ຕໍ່າສຸດ MASL | CH2: Plan WL masl | CI2: ລະດັບນໍ້າຈີງ (ນໍ້າປາ) MASL | CJ2: ແຜນພະລັງງານ (GWh) | CK2: ພະລັງງານຈີງ (GWh) | CL2: ປະລິມານ ນໍ້າຝົນ (mm) | CM2: ແຜນນໍ້າເຂົ້າ (MCM) | CN2: ນໍ້າເຂົ້າ (MCM) | CO2: ນໍ້າອອກTB discharge (MCM) | CP2: ນໍ້າລົ້ນ Overflow (MCM) | CQ2: ບໍລິມາດນໍ້າໃນອ່າງ (MCM) | CR2: % ນໍ້າໃນອ່າງ | CS2: ນໍ້າໃຊ້ໄດ້ (MCM) | CT2: % ນໍ້າໃຊ້ໄດ້ | CU2: ລະດັບນໍ້າ ສູງສຸດ MASL | CV2: ລະດັບນໍ້າ ຕໍ່າສຸດ MASL | CW2: Plan WL masl | CX2: ລະດັບນໍ້າຈີງ (ພູໂປ່ງ) MASL | CY2: ແຜນພະລັງງານ (GWh) | CZ2: ພະລັງງານຈີງ (GWh)
A3: 44562 | S3: 0.93586565 | T3: 0 | U3: 0.152064 | V3: =_xll.SRS1Splines.Functions25.Linear_Interp(V_NK3!$P$8:$P$32,V_NK3!$R$8:$R$32,AC3) -> 578.20201 | W3: =(V3/V_NK3!$R$28)*100 -> 106.65039 | X3: =V3-V_NK3!$R$8 -> 521.62336 | Y3: =IFERROR((V3 - V_NK3!$V$10) / (V_NK3!$V$9- V_NK3!$V$10) * 100, 0) -> 107.42529 | Z3: 541.8 | AA3: 521 | AB3: 541.8 | AC3: 541.92 | AD3: 0 | AE3: 0 | AH3: 0.30883567 | AI3: 2.2309236 | AJ3: 0 | AK3: =_xll.SRS1Splines.Functions25.Linear_Interp(V_NK2!$R$10:$R$21,V_NK2!$T$10:$T$21,AR3) -> 53.882029 | AL3: =(AK3/V_NK2!$T$18)*100 -> 75.465026 | AM3: =AK3-V_NK2!$T$11 -> 13.062029 | AN3: =IFERROR((AK3 - V_NK2!$X$12) / (V_NK2!$X$11- V_NK2!$X$12) * 100, 0) -> 42.714286 | AO3: 427 | AP3: 420 | AQ3: 425 | AR3: 422.99 | AS3: 0.78 | AT3: 0.54 | BN3: =_xll.SRS1Splines.Functions25.Linear_Interp(V_XNN1!$K$3:$K$8,V_XNN1!$L$3:$L$8,BT3) -> Error reading input X value(s): The value is not a number | BO3: =(BN3/V_XNN1!$L$7)*100 -> #VALUE! | BP3: =_xll.SRS1Splines.Functions25.Linear_Interp(V_XNN1!$K$3:$K$8,V_XNN1!$M$3:$M$8,BT3) -> Error reading input X value(s): The value is not a number | BQ3: =IFERROR((BN3 - V_XNN1!$M$16) / (V_XNN1!$M$15- V_XNN1!$M$16) * 100, 0) -> 0 | BR3: 252 | BS3: 249 | CO3: (MCM)
A4: 44563 | S4: 1.4869919 | T4: 0 | U4: 3.446496 | V4: =_xll.SRS1Splines.Functions25.Linear_Interp(V_NK3!$P$8:$P$32,V_NK3!$R$8:$R$32,AC4) -> 576.24251 | W4: =(V4/V_NK3!$R$28)*100 -> 106.28895 | X4: =V4-V_NK3!$R$8 -> 519.66386 | Y4: =IFERROR((V4 - V_NK3!$V$10) / (V_NK3!$V$9- V_NK3!$V$10) * 100, 0) -> 107.02174 | Z4: 541.8 | AA4: 521 | AB4: 541.8 | AC4: 541.87 | AD4: 0 | AE4: 0 | AH4: 0.228096 | AI4: 2.2213795 | AJ4: 0 | AK4: =_xll.SRS1Splines.Functions25.Linear_Interp(V_NK2!$R$10:$R$21,V_NK2!$T$10:$T$21,AR4) -> 54.231514 | AL4: =(AK4/V_NK2!$T$18)*100 -> 75.954502 | AM4: =AK4-V_NK2!$T$11 -> 13.411514 | AN4: =IFERROR((AK4 - V_NK2!$X$12) / (V_NK2!$X$11- V_NK2!$X$12) * 100, 0) -> 43.857143 | AO4: 427 | AP4: 420 | AQ4: 425 | AR4: 423.07 | AS4: 0.78 | AT4: 0.54 | BN4: =_xll.SRS1Splines.Functions25.Linear_Interp(V_XNN1!$K$3:$K$8,V_XNN1!$L$3:$L$8,BT4) -> Error reading input X value(s): The value is not a number | BO4: =(BN4/V_XNN1!$L$7)*100 -> #VALUE! | BP4: =_xll.SRS1Splines.Functions25.Linear_Interp(V_XNN1!$K$3:$K$8,V_XNN1!$M$3:$M$8,BT4) -> Error reading input X value(s): The value is not a number | BQ4: =IFERROR((BN4 - V_XNN1!$M$16) / (V_XNN1!$M$15- V_XNN1!$M$16) * 100, 0) -> 0 | BR4: 252 | BS4: 249
A5: 44564 | S5: 0.32775325 | T5: 0 | U5: 5.422464 | V5: =_xll.SRS1Splines.Functions25.Linear_Interp(V_NK3!$P$8:$P$32,V_NK3!$R$8:$R$32,AC5) -> 571.1478 | W5: =(V5/V_NK3!$R$28)*100 -> 105.34922 | X5: =V5-V_NK3!$R$8 -> 514.56915 | Y5: =IFERROR((V5 - V_NK3!$V$10) / (V_NK3!$V$9- V_NK3!$V$10) * 100, 0) -> 105.97252 | Z5: 541.8 | AA5: 521 | AB5: 541.8 | AC5: 541.74 | AD5: 0 | AE5: 0 | AH5: 0.2052864 | AI5: 2.2341735 | AJ5: 0 | AK5: =_xll.SRS1Splines.Functions25.Linear_Interp(V_NK2!$R$10:$R$21,V_NK2!$T$10:$T$21,AR5) -> 56.896343 | AL5: =(AK5/V_NK2!$T$18)*100 -> 79.686755 | AM5: =AK5-V_NK2!$T$11 -> 16.076343 | AN5: =IFERROR((AK5 - V_NK2!$X$12) / (V_NK2!$X$11- V_NK2!$X$12) * 100, 0) -> 52.571429 | AO5: 427 | AP5: 420 | AQ5: 425 | AR5: 423.68 | AS5: 0.78 | AT5: 0.54 | BN5: =_xll.SRS1Splines.Functions25.Linear_Interp(V_XNN1!$K$3:$K$8,V_XNN1!$L$3:$L$8,BT5) -> Error reading input X value(s): The value is not a number | BO5: =(BN5/V_XNN1!$L$7)*100 -> #VALUE! | BP5: =_xll.SRS1Splines.Functions25.Linear_Interp(V_XNN1!$K$3:$K$8,V_XNN1!$M$3:$M$8,BT5) -> Error reading input X value(s): The value is not a number | BQ5: =IFERROR((BN5 - V_XNN1!$M$16) / (V_XNN1!$M$15- V_XNN1!$M$16) * 100, 0) -> 0 | BR5: 252 | BS5: 249
A6: 44565 | S6: 0.95319352 | T6: 0 | U6: 2.128896 | V6: =_xll.SRS1Splines.Functions25.Linear_Interp(V_NK3!$P$8:$P$32,V_NK3!$R$8:$R$32,AC6) -> 569.9721 | W6: =(V6/V_NK3!$R$28)*100 -> 105.13236 | X6: =V6-V_NK3!$R$8 -> 513.39344 | Y6: =IFERROR((V6 - V_NK3!$V$10) / (V_NK3!$V$9- V_NK3!$V$10) * 100, 0) -> 105.73039 | Z6: 541.8 | AA6: 521 | AB6: 541.8 | AC6: 541.71 | AD6: 0 | AE6: 0 | AH6: 0.156816 | AI6: 2.2324457 | AJ6: 0 | AK6: =_xll.SRS1Splines.Functions25.Linear_Interp(V_NK2!$R$10:$R$21,V_NK2!$T$10:$T$21,AR6) -> 57.464257 | AL6: =(AK6/V_NK2!$T$18)*100 -> 80.482153 | AM6: =AK6-V_NK2!$T$11 -> 16.644257 | AN6: =IFERROR((AK6 - V_NK2!$X$12) / (V_NK2!$X$11- V_NK2!$X$12) * 100, 0) -> 54.428571 | AO6: 427 | AP6: 420 | AQ6: 425 | AR6: 423.81 | AS6: 0.78 | AT6: 0.54 | BN6: =_xll.SRS1Splines.Functions25.Linear_Interp(V_XNN1!$K$3:$K$8,V_XNN1!$L$3:$L$8,BT6) -> Error reading input X value(s): The value is not a number | BO6: =(BN6/V_XNN1!$L$7)*100 -> #VALUE! | BP6: =_xll.SRS1Splines.Functions25.Linear_Interp(V_XNN1!$K$3:$K$8,V_XNN1!$M$3:$M$8,BT6) -> Error reading input X value(s): The value is not a number | BQ6: =IFERROR((BN6 - V_XNN1!$M$16) / (V_XNN1!$M$15- V_XNN1!$M$16) * 100, 0) -> 0 | BR6: 252 | BS6: 249
A7: 44566 | S7: 0.44287683 | T7: 0 | U7: 0.050976 | V7: =_xll.SRS1Splines.Functions25.Linear_Interp(V_NK3!$P$8:$P$32,V_NK3!$R$8:$R$32,AC7) -> 570.364 | W7: =(V7/V_NK3!$R$28)*100 -> 105.20465 | X7: =V7-V_NK3!$R$8 -> 513.78535 | Y7: =IFERROR((V7 - V_NK3!$V$10) / (V_NK3!$V$9- V_NK3!$V$10) * 100, 0) -> 105.8111 | Z7: 541.8 | AA7: 521 | AB7: 541.8 | AC7: 541.72 | AD7: 0 | AE7: 0 | AH7: 0.14614935 | AI7: 0 | AJ7: 0 | AK7: =_xll.SRS1Splines.Functions25.Linear_Interp(V_NK2!$R$10:$R$21,V_NK2!$T$10:$T$21,AR7) -> 57.726371 | AL7: =(AK7/V_NK2!$T$18)*100 -> 80.84926 | AM7: =AK7-V_NK2!$T$11 -> 16.906371 | AN7: =IFERROR((AK7 - V_NK2!$X$12) / (V_NK2!$X$11- V_NK2!$X$12) * 100, 0) -> 55.285714 | AO7: 427 | AP7: 420 | AQ7: 425 | AR7: 423.87 | AS7: 0.78 | AT7: 0 | BN7: =_xll.SRS1Splines.Functions25.Linear_Interp(V_XNN1!$K$3:$K$8,V_XNN1!$L$3:$L$8,BT7) -> Error reading input X value(s): The value is not a number | BO7: =(BN7/V_XNN1!$L$7)*100 -> #VALUE! | BP7: =_xll.SRS1Splines.Functions25.Linear_Interp(V_XNN1!$K$3:$K$8,V_XNN1!$M$3:$M$8,BT7) -> Error reading input X value(s): The value is not a number | BQ7: =IFERROR((BN7 - V_XNN1!$M$16) / (V_XNN1!$M$15- V_XNN1!$M$16) * 100, 0) -> 0 | BR7: 252 | BS7: 249
A8: 44567 | S8: 0.78380165 | T8: 0 | U8: 0 | V8: =_xll.SRS1Splines.Functions25.Linear_Interp(V_NK3!$P$8:$P$32,V_NK3!$R$8:$R$32,AC8) -> 571.1478 | W8: =(V8/V_NK3!$R$28)*100 -> 105.34922 | X8: =V8-V_NK3!$R$8 -> 514.56915 | Y8: =IFERROR((V8 - V_NK3!$V$10) / (V_NK3!$V$9- V_NK3!$V$10) * 100, 0) -> 105.97252 | Z8: 541.8 | AA8: 521 | AB8: 541.8 | AC8: 541.74 | AD8: 0 | AE8: 0 | AH8: 0.25865455 | AI8: 0.61945874 | AJ8: 0 | AK8: =_xll.SRS1Splines.Functions25.Linear_Interp(V_NK2!$R$10:$R$21,V_NK2!$T$10:$T$21,AR8) -> 57.3332 | AL8: =(AK8/V_NK2!$T$18)*100 -> 80.298599 | AM8: =AK8-V_NK2!$T$11 -> 16.5132 | AN8: =IFERROR((AK8 - V_NK2!$X$12) / (V_NK2!$X$11- V_NK2!$X$12) * 100, 0) -> 54 | AO8: 427 | AP8: 420 | AQ8: 425 | AR8: 423.78 | AS8: 0.78 | AT8: 0.15 | BN8: =_xll.SRS1Splines.Functions25.Linear_Interp(V_XNN1!$K$3:$K$8,V_XNN1!$L$3:$L$8,BT8) -> Error reading input X value(s): The value is not a number | BO8: =(BN8/V_XNN1!$L$7)*100 -> #VALUE! | BP8: =_xll.SRS1Splines.Functions25.Linear_Interp(V_XNN1!$K$3:$K$8,V_XNN1!$M$3:$M$8,BT8) -> Error reading input X value(s): The value is not a number | BQ8: =IFERROR((BN8 - V_XNN1!$M$16) / (V_XNN1!$M$15- V_XNN1!$M$16) * 100, 0) -> 0 | BR8: 252 | BS8: 249
A9: 44568 | S9: 0.78380165 | T9: 0 | U9: 0 | V9: =_xll.SRS1Splines.Functions25.Linear_Interp(V_NK3!$P$8:$P$32,V_NK3!$R$8:$R$32,AC9) -> 571.9316 | W9: =(V9/V_NK3!$R$28)*100 -> 105.4938 | X9: =V9-V_NK3!$R$8 -> 515.35295 | Y9: =IFERROR((V9 - V_NK3!$V$10) / (V_NK3!$V$9- V_NK3!$V$10) * 100, 0) -> 106.13394 | Z9: 541.8 | AA9: 521 | AB9: 541.8 | AC9: 541.76 | AD9: 0 | AE9: 0 | AH9: 0.25865455 | AI9: 1.7548314 | AJ9: 0 | AK9: =_xll.SRS1Splines.Functions25.Linear_Interp(V_NK2!$R$10:$R$21,V_NK2!$T$10:$T$21,AR9) -> 55.935257 | AL9: =(AK9/V_NK2!$T$18)*100 -> 78.340696 | AM9: =AK9-V_NK2!$T$11 -> 15.115257 | AN9: =IFERROR((AK9 - V_NK2!$X$12) / (V_NK2!$X$11- V_NK2!$X$12) * 100, 0) -> 49.428571 | AO9: 427 | AP9: 420 | AQ9: 425 | AR9: 423.46 | AS9: 0.78 | AT9: 0.42 | BN9: =_xll.SRS1Splines.Functions25.Linear_Interp(V_XNN1!$K$3:$K$8,V_XNN1!$L$3:$L$8,BT9) -> Error reading input X value(s): The value is not a number | BO9: =(BN9/V_XNN1!$L$7)*100 -> #VALUE! | BP9: =_xll.SRS1Splines.Functions25.Linear_Interp(V_XNN1!$K$3:$K$8,V_XNN1!$M$3:$M$8,BT9) -> Error reading input X value(s): The value is not a number | BQ9: =IFERROR((BN9 - V_XNN1!$M$16) / (V_XNN1!$M$15- V_XNN1!$M$16) * 100, 0) -> 0 | BR9: 252 | BS9: 249
A10: 44569 | S10: 0.78380165 | T10: 0 | U10: 0 | V10: =_xll.SRS1Splines.Functions25.Linear_Interp(V_NK3!$P$8:$P$32,V_NK3!$R$8:$R$32,AC10) -> 572.7154 | W10: =(V10/V_NK3!$R$28)*100 -> 105.63837 | X10: =V10-V_NK3!$R$8 -> 516.13675 | Y10: =IFERROR((V10 - V_NK3!$V$10) / (V_NK3!$V$9- V_NK3!$V$10) * 100, 0) -> 106.29536 | Z10: 541.8 | AA10: 521 | AB10: 541.8 | AC10: 541.78 | AD10: 0 | AE10: 0 | AH10: 0.25865455 | AI10: 1.7008581 | AJ10: 0 | AK10: =_xll.SRS1Splines.Functions25.Linear_Interp(V_NK2!$R$10:$R$21,V_NK2!$T$10:$T$21,AR10) -> 54.537314 | AL10: =(AK10/V_NK2!$T$18)*100 -> 76.382793 | AM10: =AK10-V_NK2!$T$11 -> 13.717314 | AN10: =IFERROR((AK10 - V_NK2!$X$12) / (V_NK2!$X$11- V_NK2!$X$12) * 100, 0) -> 44.857143 | AO10: 427 | AP10: 420 | AQ10: 425 | AR10: 423.14 | AS10: 0.78 | AT10: 0.41 | BN10: =_xll.SRS1Splines.Functions25.Linear_Interp(V_XNN1!$K$3:$K$8,V_XNN1!$L$3:$L$8,BT10) -> Error reading input X value(s): The value is not a number | BO10: =(BN10/V_XNN1!$L$7)*100 -> #VALUE! | BP10: =_xll.SRS1Splines.Functions25.Linear_Interp(V_XNN1!$K$3:$K$8,V_XNN1!$M$3:$M$8,BT10) -> Error reading input X value(s): The value is not a number | BQ10: =IFERROR((BN10 - V_XNN1!$M$16) / (V_XNN1!$M$15- V_XNN1!$M$16) * 100, 0) -> 0 | BR10: 252 | BS10: 249
A11: 44570 | S11: 0.39190083 | T11: 0 | U11: 0 | V11: =_xll.SRS1Splines.Functions25.Linear_Interp(V_NK3!$P$8:$P$32,V_NK3!$R$8:$R$32,AC11) -> 573.1073 | W11: =(V11/V_NK3!$R$28)*100 -> 105.71066 | X11: =V11-V_NK3!$R$8 -> 516.52865 | Y11: =IFERROR((V11 - V_NK3!$V$10) / (V_NK3!$V$9- V_NK3!$V$10) * 100, 0) -> 106.37607 | Z11: 541.8 | AA11: 521 | AB11: 541.8 | AC11: 541.79 | AD11: 0 | AE11: 0 | AH11: 0.12932727 | AI11: 1.6599256 | AJ11: 0 | AK11: =_xll.SRS1Splines.Functions25.Linear_Interp(V_NK2!$R$10:$R$21,V_NK2!$T$10:$T$21,AR11) -> 53.183057 | AL11: =(AK11/V_NK2!$T$18)*100 -> 74.486074 | AM11: =AK11-V_NK2!$T$11 -> 12.363057 | AN11: =IFERROR((AK11 - V_NK2!$X$12) / (V_NK2!$X$11- V_NK2!$X$12) * 100, 0) -> 40.428571 | AO11: 427 | AP11: 420 | AQ11: 425 | AR11: 422.83 | AS11: 0.78 | AT11: 0.4 | BN11: =_xll.SRS1Splines.Functions25.Linear_Interp(V_XNN1!$K$3:$K$8,V_XNN1!$L$3:$L$8,BT11) -> Error reading input X value(s): The value is not a number | BO11: =(BN11/V_XNN1!$L$7)*100 -> #VALUE! | BP11: =_xll.SRS1Splines.Functions25.Linear_Interp(V_XNN1!$K$3:$K$8,V_XNN1!$M$3:$M$8,BT11) -> Error reading input X value(s): The value is not a number | BQ11: =IFERROR((BN11 - V_XNN1!$M$16) / (V_XNN1!$M$15- V_XNN1!$M$16) * 100, 0) -> 0 | BR11: 252 | BS11: 249
A12: 44571 | S12: 0.39190083 | T12: 0 | U12: 0 | V12: =_xll.SRS1Splines.Functions25.Linear_Interp(V_NK3!$P$8:$P$32,V_NK3!$R$8:$R$32,AC12) -> 573.4992 | W12: =(V12/V_NK3!$R$28)*100 -> 105.78294 | X12: =V12-V_NK3!$R$8 -> 516.92055 | Y12: =IFERROR((V12 - V_NK3!$V$10) / (V_NK3!$V$9- V_NK3!$V$10) * 100, 0) -> 106.45678 | Z12: 541.8 | AA12: 521 | AB12: 541.8 | AC12: 541.8 | AD12: 0 | AE12: 0 | AH12: 0.12932727 | AI12: 1.721962 | AJ12: 0 | AK12: =_xll.SRS1Splines.Functions25.Linear_Interp(V_NK2!$R$10:$R$21,V_NK2!$T$10:$T$21,AR12) -> 51.697743 | AL12: =(AK12/V_NK2!$T$18)*100 -> 72.405802 | AM12: =AK12-V_NK2!$T$11 -> 10.877743 | AN12: =IFERROR((AK12 - V_NK2!$X$12) / (V_NK2!$X$11- V_NK2!$X$12) * 100, 0) -> 35.571429 | AO12: 427 | AP12: 420 | AQ12: 425 | AR12: 422.49 | AS12: 0.78 | AT12: 0.41 | BN12: =_xll.SRS1Splines.Functions25.Linear_Interp(V_XNN1!$K$3:$K$8,V_XNN1!$L$3:$L$8,BT12) -> Error reading input X value(s): The value is not a number | BO12: =(BN12/V_XNN1!$L$7)*100 -> #VALUE! | BP12: =_xll.SRS1Splines.Functions25.Linear_Interp(V_XNN1!$K$3:$K$8,V_XNN1!$M$3:$M$8,BT12) -> Error reading input X value(s): The value is not a number | BQ12: =IFERROR((BN12 - V_XNN1!$M$16) / (V_XNN1!$M$15- V_XNN1!$M$16) * 100, 0) -> 0 | BR12: 252 | BS12: 249
A13: 44572 | S13: 0.39190083 | T13: 0 | U13: 0 | V13: =_xll.SRS1Splines.Functions25.Linear_Interp(V_NK3!$P$8:$P$32,V_NK3!$R$8:$R$32,AC13) -> 573.8911 | W13: =(V13/V_NK3!$R$28)*100 -> 105.85523 | X13: =V13-V_NK3!$R$8 -> 517.31245 | Y13: =IFERROR((V13 - V_NK3!$V$10) / (V_NK3!$V$9- V_NK3!$V$10) * 100, 0) -> 106.53748 | Z13: 541.8 | AA13: 521 | AB13: 541.8 | AC13: 541.81 | AD13: 0 | AE13: 0 | AH13: 0.12932727 | AI13: 1.8223392 | AJ13: 0 | AK13: =_xll.SRS1Splines.Functions25.Linear_Interp(V_NK2!$R$10:$R$21,V_NK2!$T$10:$T$21,AR13) -> 50.081371 | AL13: =(AK13/V_NK2!$T$18)*100 -> 70.141977 | AM13: =AK13-V_NK2!$T$11 -> 9.2613714 | AN13: =IFERROR((AK13 - V_NK2!$X$12) / (V_NK2!$X$11- V_NK2!$X$12) * 100, 0) -> 30.285714 | AO13: 427 | AP13: 420 | AQ13: 425 | AR13: 422.12 | AS13: 0.78 | AT13: 0.44 | BN13: =_xll.SRS1Splines.Functions25.Linear_Interp(V_XNN1!$K$3:$K$8,V_XNN1!$L$3:$L$8,BT13) -> Error reading input X value(s): The value is not a number | BO13: =(BN13/V_XNN1!$L$7)*100 -> #VALUE! | BP13: =_xll.SRS1Splines.Functions25.Linear_Interp(V_XNN1!$K$3:$K$8,V_XNN1!$M$3:$M$8,BT13) -> Error reading input X value(s): The value is not a number | BQ13: =IFERROR((BN13 - V_XNN1!$M$16) / (V_XNN1!$M$15- V_XNN1!$M$16) * 100, 0) -> 0 | BR13: 252 | BS13: 249
A14: 44573 | S14: 0.78380165 | T14: 0 | U14: 0 | V14: =_xll.SRS1Splines.Functions25.Linear_Interp(V_NK3!$P$8:$P$32,V_NK3!$R$8:$R$32,AC14) -> 574.67491 | W14: =(V14/V_NK3!$R$28)*100 -> 105.9998 | X14: =V14-V_NK3!$R$8 -> 518.09625 | Y14: =IFERROR((V14 - V_NK3!$V$10) / (V_NK3!$V$9- V_NK3!$V$10) * 100, 0) -> 106.6989 | Z14: 541.8 | AA14: 521 | AB14: 541.8 | AC14: 541.83 | AD14: 0 | AE14: 0 | AH14: 0.25865455 | AI14: 1.8093807 | AJ14: 0 | AK14: =_xll.SRS1Splines.Functions25.Linear_Interp(V_NK2!$R$10:$R$21,V_NK2!$T$10:$T$21,AR14) -> 48.421314 | AL14: =(AK14/V_NK2!$T$18)*100 -> 67.816967 | AM14: =AK14-V_NK2!$T$11 -> 7.6013143 | AN14: =IFERROR((AK14 - V_NK2!$X$12) / (V_NK2!$X$11- V_NK2!$X$12) * 100, 0) -> 24.857143 | AO14: 427 | AP14: 420 | AQ14: 425 | AR14: 421.74 | AS14: 0.78 | AT14: 0.44 | BN14: =_xll.SRS1Splines.Functions25.Linear_Interp(V_XNN1!$K$3:$K$8,V_XNN1!$L$3:$L$8,BT14) -> Error reading input X value(s): The value is not a number | BO14: =(BN14/V_XNN1!$L$7)*100 -> #VALUE! | BP14: =_xll.SRS1Splines.Functions25.Linear_Interp(V_XNN1!$K$3:$K$8,V_XNN1!$M$3:$M$8,BT14) -> Error reading input X value(s): The value is not a number | BQ14: =IFERROR((BN14 - V_XNN1!$M$16) / (V_XNN1!$M$15- V_XNN1!$M$16) * 100, 0) -> 0 | BR14: 252 | BS14: 249
A15: 44574 | S15: -4.4380708 | T15: 0 | U15: 0.65664 | V15: =_xll.SRS1Splines.Functions25.Linear_Interp(V_NK3!$P$8:$P$32,V_NK3!$R$8:$R$32,AC15) -> 569.5802 | W15: =(V15/V_NK3!$R$28)*100 -> 105.06008 | X15: =V15-V_NK3!$R$8 -> 513.00154 | Y15: =IFERROR((V15 - V_NK3!$V$10) / (V_NK3!$V$9- V_NK3!$V$10) * 100, 0) -> 105.64968 | Z15: 541.8 | AA15: 521 | AB15: 541.8 | AC15: 541.7 | AD15: 0 | AE15: 0 | AH15: 0.21384 | AI15: 3.7569033 | AJ15: 0 | AK15: =_xll.SRS1Splines.Functions25.Linear_Interp(V_NK2!$R$10:$R$21,V_NK2!$T$10:$T$21,AR15) -> 44.839086 | AL15: =(AK15/V_NK2!$T$18)*100 -> 62.79984 | AM15: =AK15-V_NK2!$T$11 -> 4.0190857 | AN15: =IFERROR((AK15 - V_NK2!$X$12) / (V_NK2!$X$11- V_NK2!$X$12) * 100, 0) -> 13.142857 | AO15: 427 | AP15: 420 | AQ15: 425 | AR15: 420.92 | AS15: 0.78 | AT15: 0.91 | BN15: =_xll.SRS1Splines.Functions25.Linear_Interp(V_XNN1!$K$3:$K$8,V_XNN1!$L$3:$L$8,BT15) -> Error reading input X value(s): The value is not a number | BO15: =(BN15/V_XNN1!$L$7)*100 -> #VALUE! | BP15: =_xll.SRS1Splines.Functions25.Linear_Interp(V_XNN1!$K$3:$K$8,V_XNN1!$M$3:$M$8,BT15) -> Error reading input X value(s): The value is not a number | BQ15: =IFERROR((BN15 - V_XNN1!$M$16) / (V_XNN1!$M$15- V_XNN1!$M$16) * 100, 0) -> 0 | BR15: 252 | BS15: 249
... A367: 44926 | S367: 1.0457699 | T367: 1.7415 | U367: 0 | V367: =_xll.SRS1Splines.Functions25.Linear_Interp(V_NK3!$P$8:$P$32,V_NK3!$R$8:$R$32,AC367) -> 463.533 | W367: =(V367/V_NK3!$R$28)*100 -> 85.499482 | X367: =V367-V_NK3!$R$8 -> 406.95435 | Y367: =IFERROR((V367 - V_NK3!$V$10) / (V_NK3!$V$9- V_NK3!$V$10) * 100, 0) -> 83.809876 | Z367: 541.8 | AA367: 521 | AB367: 540.84 | AC367: 538.87 | AD367: 0.62 | AE367: 0.43 | AH367: 1.9124541 | AI367: 2.71512 | AJ367: 0 | AK367: =_xll.SRS1Splines.Functions25.Linear_Interp(V_NK2!$R$10:$R$21,V_NK2!$T$10:$T$21,AR367) -> 71.356314 | AL367: =(AK367/V_NK2!$T$18)*100 -> 99.938816 | AM367: =AK367-V_NK2!$T$11 -> 30.536314 | AN367: =IFERROR((AK367 - V_NK2!$X$12) / (V_NK2!$X$11- V_NK2!$X$12) * 100, 0) -> 99.857143 | AO367: 427 | AP367: 420 | AQ367: 425 | AR367: 426.99 | AS367: 0.82 | AT367: 0.66 | BN367: =_xll.SRS1Splines.Functions25.Linear_Interp(V_XNN1!$K$3:$K$8,V_XNN1!$L$3:$L$8,BT367) -> Error reading input X value(s): The value is not a number | BO367: =(BN367/V_XNN1!$L$7)*100 -> #VALUE! | BP367: =_xll.SRS1Splines.Functions25.Linear_Interp(V_XNN1!$K$3:$K$8,V_XNN1!$M$3:$M$8,BT367) -> Error reading input X value(s): The value is not a number | BQ367: =IFERROR((BN367 - V_XNN1!$M$16) / (V_XNN1!$M$15- V_XNN1!$M$16) * 100, 0) -> 0 | BR367: 252 | BS367: 249
A368: 44927 | S368: 0.71504572 | T368: 0.71504572 | U368: 0 | V368: =_xll.SRS1Splines.Functions25.Linear_Interp(V_NK3!$P$8:$P$32,V_NK3!$R$8:$R$32,AC368) -> 463.533 | W368: =(V368/V_NK3!$R$28)*100 -> 85.499482 | X368: =V368-V_NK3!$R$8 -> 406.95435 | Y368: =IFERROR((V368 - V_NK3!$V$10) / (V_NK3!$V$9- V_NK3!$V$10) * 100, 0) -> 83.809876 | Z368: 541.8 | AA368: 521 | AB368: 537.86 | AC368: 538.87 | AD368: 0.43193548 | AE368: 0.1765545 | AH368: 0.87950624 | AI368: 2.0980473 | AJ368: 0 | AK368: =_xll.SRS1Splines.Functions25.Linear_Interp(V_NK2!$R$10:$R$21,V_NK2!$T$10:$T$21,AR368) -> 70.438914 | AL368: =(AK368/V_NK2!$T$18)*100 -> 98.653942 | AM368: =AK368-V_NK2!$T$11 -> 29.618914 | AN368: =IFERROR((AK368 - V_NK2!$X$12) / (V_NK2!$X$11- V_NK2!$X$12) * 100, 0) -> 96.857143 | AO368: 427 | AP368: 420 | AQ368: 427 | AR368: 426.78 | AS368: 0.52806452 | AT368: 0.511413 | BK368: 0.4550443 | BL368: 0.45487764 | BM368: =BK368-BL368 -> 0.00016666667 | BN368: =_xll.SRS1Splines.Functions25.Linear_Interp(V_XNN1!$K$3:$K$8,V_XNN1!$L$3:$L$8,BT368) -> 0.201 | BO368: =(BN368/V_XNN1!$L$7)*100 -> 95.714286 | BP368: =_xll.SRS1Splines.Functions25.Linear_Interp(V_XNN1!$K$3:$K$8,V_XNN1!$M$3:$M$8,BT368) -> 0.045 | BQ368: =IFERROR((BN368 - V_XNN1!$M$16) / (V_XNN1!$M$15- V_XNN1!$M$16) * 100, 0) -> 44.568245 | BR368: 252 | BS368: 249 | BT368: 251.5 | BU368: 0.096 | BV368: 0.065296
A369: 44928 | S369: 0.41103278 | T369: 1.802493 | U369: 0 | V369: =_xll.SRS1Splines.Functions25.Linear_Interp(V_NK3!$P$8:$P$32,V_NK3!$R$8:$R$32,AC369) -> 462.14154 | W369: =(V369/V_NK3!$R$28)*100 -> 85.242825 | X369: =V369-V_NK3!$R$8 -> 405.56289 | Y369: =IFERROR((V369 - V_NK3!$V$10) / (V_NK3!$V$9- V_NK3!$V$10) * 100, 0) -> 83.523313 | Z369: 541.8 | AA369: 521 | AB369: 537.86 | AC369: 538.83 | AD369: 0.43193548 | AE369: 0.44506 | AH369: 1.7578845 | AI369: 2.0980473 | AJ369: 0 | AK369: =_xll.SRS1Splines.Functions25.Linear_Interp(V_NK2!$R$10:$R$21,V_NK2!$T$10:$T$21,AR369) -> 70.220486 | AL369: =(AK369/V_NK2!$T$18)*100 -> 98.348019 | AM369: =AK369-V_NK2!$T$11 -> 29.400486 | AN369: =IFERROR((AK369 - V_NK2!$X$12) / (V_NK2!$X$11- V_NK2!$X$12) * 100, 0) -> 96.142857 | AO369: 427 | AP369: 420 | AQ369: 427 | AR369: 426.73 | AS369: 0.52806452 | AT369: 0.512804 | BK369: 0.42914417 | BL369: 0.42926917 | BM369: =BK369-BL369 -> -0.000125 | BN369: =_xll.SRS1Splines.Functions25.Linear_Interp(V_XNN1!$K$3:$K$8,V_XNN1!$L$3:$L$8,BT369) -> 0.1992 | BO369: =(BN369/V_XNN1!$L$7)*100 -> 94.857143 | BP369: =_xll.SRS1Splines.Functions25.Linear_Interp(V_XNN1!$K$3:$K$8,V_XNN1!$M$3:$M$8,BT369) -> 0.0432 | BQ369: =IFERROR((BN369 - V_XNN1!$M$16) / (V_XNN1!$M$15- V_XNN1!$M$16) * 100, 0) -> 38.997214 | BR369: 252 | BS369: 249 | BT369: 251.4 | BU369: 0.096 | BV369: 0.06162
A370: 44929 | S370: 0.75764234 | T370: 1.8012375 | U370: 0 | V370: =_xll.SRS1Splines.Functions25.Linear_Interp(V_NK3!$P$8:$P$32,V_NK3!$R$8:$R$32,AC370) -> 461.09794 | W370: =(V370/V_NK3!$R$28)*100 -> 85.050332 | X370: =V370-V_NK3!$R$8 -> 404.51929 | Y370: =IFERROR((V370 - V_NK3!$V$10) / (V_NK3!$V$9- V_NK3!$V$10) * 100, 0) -> 83.30839 | Z370: 541.8 | AA370: 521 | AB370: 537.86 | AC370: 538.8 | AD370: 0.43193548 | AE370: 0.44475 | AH370: 1.8711357 | AI370: 2.2214618 | AJ370: 0 | AK370: =_xll.SRS1Splines.Functions25.Linear_Interp(V_NK2!$R$10:$R$21,V_NK2!$T$10:$T$21,AR370) -> 69.914686 | AL370: =(AK370/V_NK2!$T$18)*100 -> 97.919728 | AM370: =AK370-V_NK2!$T$11 -> 29.094686 | AN370: =IFERROR((AK370 - V_NK2!$X$12) / (V_NK2!$X$11- V_NK2!$X$12) * 100, 0) -> 95.142857 | AO370: 427 | AP370: 420 | AQ370: 427 | AR370: 426.66 | AS370: 0.52806452 | AT370: 0.539201 | BK370: 0.48519644 | BL370: 0.48552977 | BM370: =BK370-BL370 -> -0.00033333333 | BN370: =_xll.SRS1Splines.Functions25.Linear_Interp(V_XNN1!$K$3:$K$8,V_XNN1!$L$3:$L$8,BT370) -> 0.183 | BO370: =(BN370/V_XNN1!$L$7)*100 -> 87.142857 | BP370: =_xll.SRS1Splines.Functions25.Linear_Interp(V_XNN1!$K$3:$K$8,V_XNN1!$M$3:$M$8,BT370) -> 0.027 | BQ370: =IFERROR((BN370 - V_XNN1!$M$16) / (V_XNN1!$M$15- V_XNN1!$M$16) * 100, 0) -> -11.142061 | BR370: 252 | BS370: 249 | BT370: 250.5 | BU370: 0.096 | BV370: 0.069696
A371: 44930 | S371: 0.40856228 | T371: 1.8000225 | U371: 0 | V371: =_xll.SRS1Splines.Functions25.Linear_Interp(V_NK3!$P$8:$P$32,V_NK3!$R$8:$R$32,AC371) -> 459.70648 | W371: =(V371/V_NK3!$R$28)*100 -> 84.793675 | X371: =V371-V_NK3!$R$8 -> 403.12783 | Y371: =IFERROR((V371 - V_NK3!$V$10) / (V_NK3!$V$9- V_NK3!$V$10) * 100, 0) -> 83.021827 | Z371: 541.8 | AA371: 521 | AB371: 537.86 | AC371: 538.76 | AD371: 0.43193548 | AE371: 0.44445 | AH371: 1.7548458 | AI371: 2.2214618 | AJ371: 0 | AK371: =_xll.SRS1Splines.Functions25.Linear_Interp(V_NK2!$R$10:$R$21,V_NK2!$T$10:$T$21,AR371) -> 69.608886 | AL371: =(AK371/V_NK2!$T$18)*100 -> 97.491437 | AM371: =AK371-V_NK2!$T$11 -> 28.788886 | AN371: =IFERROR((AK371 - V_NK2!$X$12) / (V_NK2!$X$11- V_NK2!$X$12) * 100, 0) -> 94.142857 | AO371: 427 | AP371: 420 | AQ371: 427 | AR371: 426.59 | AS371: 0.52806452 | AT371: 0.539517 | BK371: 0.43088538 | BL371: 0.43088538 | BM371: =BK371-BL371 -> 0 | BN371: =_xll.SRS1Splines.Functions25.Linear_Interp(V_XNN1!$K$3:$K$8,V_XNN1!$L$3:$L$8,BT371) -> 0.1884 | BO371: =(BN371/V_XNN1!$L$7)*100 -> 89.714286 | BP371: =_xll.SRS1Splines.Functions25.Linear_Interp(V_XNN1!$K$3:$K$8,V_XNN1!$M$3:$M$8,BT371) -> 0.0324 | BQ371: =IFERROR((BN371 - V_XNN1!$M$16) / (V_XNN1!$M$15- V_XNN1!$M$16) * 100, 0) -> 5.5710306 | BR371: 252 | BS371: 249 | BT371: 250.8 | BU371: 0.096 | BV371: 0.061852
A372: 44931 | S372: 0.75557684 | T372: 1.799172 | U372: 0 | V372: =_xll.SRS1Splines.Functions25.Linear_Interp(V_NK3!$P$8:$P$32,V_NK3!$R$8:$R$32,AC372) -> 458.66289 | W372: =(V372/V_NK3!$R$28)*100 -> 84.601182 | X372: =V372-V_NK3!$R$8 -> 402.08423 | Y372: =IFERROR((V372 - V_NK3!$V$10) / (V_NK3!$V$9- V_NK3!$V$10) * 100, 0) -> 82.806905 | Z372: 541.8 | AA372: 521 | AB372: 537.86 | AC372: 538.73 | AD372: 0.43193548 | AE372: 0.44424 | AH372: 1.8685952 | AI372: 2.1803236 | AJ372: 0 | AK372: =_xll.SRS1Splines.Functions25.Linear_Interp(V_NK2!$R$10:$R$21,V_NK2!$T$10:$T$21,AR372) -> 69.303086 | AL372: =(AK372/V_NK2!$T$18)*100 -> 97.063145 | AM372: =AK372-V_NK2!$T$11 -> 28.483086 | AN372: =IFERROR((AK372 - V_NK2!$X$12) / (V_NK2!$X$11- V_NK2!$X$12) * 100, 0) -> 93.142857 | AO372: 427 | AP372: 420 | AQ372: 427 | AR372: 426.52 | AS372: 0.52806452 | AT372: 0.529033 | BK372: 0.36123537 | BL372: 0.36123537 | BM372: =BK372-BL372 -> 0 | BN372: =_xll.SRS1Splines.Functions25.Linear_Interp(V_XNN1!$K$3:$K$8,V_XNN1!$L$3:$L$8,BT372) -> 0.19938 | BO372: =(BN372/V_XNN1!$L$7)*100 -> 94.942857 | BP372: =_xll.SRS1Splines.Functions25.Linear_Interp(V_XNN1!$K$3:$K$8,V_XNN1!$M$3:$M$8,BT372) -> 0.04338 | BQ372: =IFERROR((BN372 - V_XNN1!$M$16) / (V_XNN1!$M$15- V_XNN1!$M$16) * 100, 0) -> 39.554318 | BR372: 252 | BS372: 249 | BT372: 251.41 | BU372: 0.096 | BV372: 0.051854
A373: 44932 | S373: 0.76003184 | T373: 1.803627 | U373: 0 | V373: =_xll.SRS1Splines.Functions25.Linear_Interp(V_NK3!$P$8:$P$32,V_NK3!$R$8:$R$32,AC373) -> 457.61929 | W373: =(V373/V_NK3!$R$28)*100 -> 84.408689 | X373: =V373-V_NK3!$R$8 -> 401.04064 | Y373: =IFERROR((V373 - V_NK3!$V$10) / (V_NK3!$V$9- V_NK3!$V$10) * 100, 0) -> 82.591983 | Z373: 541.8 | AA373: 521 | AB373: 537.86 | AC373: 538.7 | AD373: 0.43193548 | AE373: 0.44534 | AH373: 1.8740748 | AI373: 2.1803236 | AJ373: 0 | AK373: =_xll.SRS1Splines.Functions25.Linear_Interp(V_NK2!$R$10:$R$21,V_NK2!$T$10:$T$21,AR373) -> 68.997286 | AL373: =(AK373/V_NK2!$T$18)*100 -> 96.634854 | AM373: =AK373-V_NK2!$T$11 -> 28.177286 | AN373: =IFERROR((AK373 - V_NK2!$X$12) / (V_NK2!$X$11- V_NK2!$X$12) * 100, 0) -> 92.142857 | AO373: 427 | AP373: 420 | AQ373: 427 | AR373: 426.45 | AS373: 0.52806452 | AT373: 0.53316 | BK373: 0.46574521 | BL373: 0.46574521 | BM373: =BK373-BL373 -> 0 | BN373: =_xll.SRS1Splines.Functions25.Linear_Interp(V_XNN1!$K$3:$K$8,V_XNN1!$L$3:$L$8,BT373) -> 0.1902 | BO373: =(BN373/V_XNN1!$L$7)*100 -> 90.571429 | BP373: =_xll.SRS1Splines.Functions25.Linear_Interp(V_XNN1!$K$3:$K$8,V_XNN1!$M$3:$M$8,BT373) -> 0.0342 | BQ373: =IFERROR((BN373 - V_XNN1!$M$16) / (V_XNN1!$M$15- V_XNN1!$M$16) * 100, 0) -> 11.142061 | BR373: 252 | BS373: 249 | BT373: 250.9 | BU373: 0.096 | BV373: 0.066856
A374: 44933 | S374: 0.41851718 | T374: 1.8099774 | U374: 0 | V374: =_xll.SRS1Splines.Functions25.Linear_Interp(V_NK3!$P$8:$P$32,V_NK3!$R$8:$R$32,AC374) -> 456.22783 | W374: =(V374/V_NK3!$R$28)*100 -> 84.152032 | X374: =V374-V_NK3!$R$8 -> 399.64918 | Y374: =IFERROR((V374 - V_NK3!$V$10) / (V_NK3!$V$9- V_NK3!$V$10) * 100, 0) -> 82.305419 | Z374: 541.8 | AA374: 521 | AB374: 537.86 | AC374: 538.66 | AD374: 0.43193548 | AE374: 0.446908 | AH374: 1.7670903 | AI374: 2.1803236 | AJ374: 0 | AK374: =_xll.SRS1Splines.Functions25.Linear_Interp(V_NK2!$R$10:$R$21,V_NK2!$T$10:$T$21,AR374) -> 68.691486 | AL374: =(AK374/V_NK2!$T$18)*100 -> 96.206563 | AM374: =AK374-V_NK2!$T$11 -> 27.871486 | AN374: =IFERROR((AK374 - V_NK2!$X$12) / (V_NK2!$X$11- V_NK2!$X$12) * 100, 0) -> 91.142857 | AO374: 427 | AP374: 420 | AQ374: 427 | AR374: 426.38 | AS374: 0.52806452 | AT374: 0.531413 | BK374: 0.37502883 | BL374: 0.37502883 | BM374: =BK374-BL374 -> 0 | BN374: =_xll.SRS1Splines.Functions25.Linear_Interp(V_XNN1!$K$3:$K$8,V_XNN1!$L$3:$L$8,BT374) -> 0.1902 | BO374: =(BN374/V_XNN1!$L$7)*100 -> 90.571429 | BP374: =_xll.SRS1Splines.Functions25.Linear_Interp(V_XNN1!$K$3:$K$8,V_XNN1!$M$3:$M$8,BT374) -> 0.0342 | BQ374: =IFERROR((BN374 - V_XNN1!$M$16) / (V_XNN1!$M$15- V_XNN1!$M$16) * 100, 0) -> 11.142061 | BR374: 252 | BS374: 249 | BT374: 250.9 | BU374: 0.096 | BV374: 0.053834
A375: 44934 | S375: 0.76250234 | T375: 1.8060975 | U375: 0 | V375: =_xll.SRS1Splines.Functions25.Linear_Interp(V_NK3!$P$8:$P$32,V_NK3!$R$8:$R$32,AC375) -> 455.18424 | W375: =(V375/V_NK3!$R$28)*100 -> 83.959539 | X375: =V375-V_NK3!$R$8 -> 398.60558 | Y375: =IFERROR((V375 - V_NK3!$V$10) / (V_NK3!$V$9- V_NK3!$V$10) * 100, 0) -> 82.090497 | Z375: 541.8 | AA375: 521 | AB375: 537.86 | AC375: 538.63 | AD375: 0.43193548 | AE375: 0.44595 | AH375: 1.8771135 | AI375: 2.1803236 | AJ375: 0 | AK375: =_xll.SRS1Splines.Functions25.Linear_Interp(V_NK2!$R$10:$R$21,V_NK2!$T$10:$T$21,AR375) -> 68.429371 | AL375: =(AK375/V_NK2!$T$18)*100 -> 95.839456 | AM375: =AK375-V_NK2!$T$11 -> 27.609371 | AN375: =IFERROR((AK375 - V_NK2!$X$12) / (V_NK2!$X$11- V_NK2!$X$12) * 100, 0) -> 90.285714 | AO375: 427 | AP375: 420 | AQ375: 427 | AR375: 426.32 | AS375: 0.52806452 | AT375: 0.528641 | BK375: 0.41787215 | BL375: 0.41787215 | BM375: =BK375-BL375 -> 0 | BN375: =_xll.SRS1Splines.Functions25.Linear_Interp(V_XNN1!$K$3:$K$8,V_XNN1!$L$3:$L$8,BT375) -> 0.1992 | BO375: =(BN375/V_XNN1!$L$7)*100 -> 94.857143 | BP375: =_xll.SRS1Splines.Functions25.Linear_Interp(V_XNN1!$K$3:$K$8,V_XNN1!$M$3:$M$8,BT375) -> 0.0432 | BQ375: =IFERROR((BN375 - V_XNN1!$M$16) / (V_XNN1!$M$15- V_XNN1!$M$16) * 100, 0) -> 38.997214 | BR375: 252 | BS375: 249 | BT375: 251.4 | BU375: 0.096 | BV375: 0.059984
A376: 44935 | S376: 0.39207878 | T376: 1.783539 | U376: 0 | V376: =_xll.SRS1Splines.Functions25.Linear_Interp(V_NK3!$P$8:$P$32,V_NK3!$R$8:$R$32,AC376) -> 453.79278 | W376: =(V376/V_NK3!$R$28)*100 -> 83.702881 | X376: =V376-V_NK3!$R$8 -> 397.21412 | Y376: =IFERROR((V376 - V_NK3!$V$10) / (V_NK3!$V$9- V_NK3!$V$10) * 100, 0) -> 81.803934 | Z376: 541.8 | AA376: 521 | AB376: 537.86 | AC376: 538.59 | AD376: 0.43193548 | AE376: 0.44038 | AH376: 1.7345711 | AI376: 2.1803236 | AJ376: 0 | AK376: =_xll.SRS1Splines.Functions25.Linear_Interp(V_NK2!$R$10:$R$21,V_NK2!$T$10:$T$21,AR376) -> 68.123571 | AL376: =(AK376/V_NK2!$T$18)*100 -> 95.411164 | AM376: =AK376-V_NK2!$T$11 -> 27.303571 | AN376: =IFERROR((AK376 - V_NK2!$X$12) / (V_NK2!$X$11- V_NK2!$X$12) * 100, 0) -> 89.285714 | AO376: 427 | AP376: 420 | AQ376: 427 | AR376: 426.25 | AS376: 0.52806452 | AT376: 0.532929 | BK376: 0.45365155 | BL376: 0.45365155 | BM376: =BK376-BL376 -> 0 | BN376: =_xll.SRS1Splines.Functions25.Linear_Interp(V_XNN1!$K$3:$K$8,V_XNN1!$L$3:$L$8,BT376) -> 0.19614 | BO376: =(BN376/V_XNN1!$L$7)*100 -> 93.4 | BP376: =_xll.SRS1Splines.Functions25.Linear_Interp(V_XNN1!$K$3:$K$8,V_XNN1!$M$3:$M$8,BT376) -> 0.04014 | BQ376: =IFERROR((BN376 - V_XNN1!$M$16) / (V_XNN1!$M$15- V_XNN1!$M$16) * 100, 0) -> 29.526462 | BR376: 252 | BS376: 249 | BT376: 251.23 | BU376: 0.06 | BV376: 0.06512
A377: 44936 | S377: 0.76622834 | T377: 1.8098235 | U377: 0 | V377: =_xll.SRS1Splines.Functions25.Linear_Interp(V_NK3!$P$8:$P$32,V_NK3!$R$8:$R$32,AC377) -> 452.74918 | W377: =(V377/V_NK3!$R$28)*100 -> 83.510388 | X377: =V377-V_NK3!$R$8 -> 396.17053 | Y377: =IFERROR((V377 - V_NK3!$V$10) / (V_NK3!$V$9- V_NK3!$V$10) * 100, 0) -> 81.589012 | Z377: 541.8 | AA377: 521 | AB377: 537.86 | AC377: 538.56 | AD377: 0.43193548 | AE377: 0.44687 | AH377: 1.8816965 | AI377: 2.1803236 | AJ377: 0 | AK377: =_xll.SRS1Splines.Functions25.Linear_Interp(V_NK2!$R$10:$R$21,V_NK2!$T$10:$T$21,AR377) -> 67.861457 | AL377: =(AK377/V_NK2!$T$18)*100 -> 95.044058 | AM377: =AK377-V_NK2!$T$11 -> 27.041457 | AN377: =IFERROR((AK377 - V_NK2!$X$12) / (V_NK2!$X$11- V_NK2!$X$12) * 100, 0) -> 88.428571 | AO377: 427 | AP377: 420 | AQ377: 427 | AR377: 426.19 | AS377: 0.52806452 | AT377: 0.534377 | BK377: 0.34848687 | BL377: 0.34848687 | BM377: =BK377-BL377 -> 0 | BN377: =_xll.SRS1Splines.Functions25.Linear_Interp(V_XNN1!$K$3:$K$8,V_XNN1!$L$3:$L$8,BT377) -> 0.19704 | BO377: =(BN377/V_XNN1!$L$7)*100 -> 93.828571 | BP377: =_xll.SRS1Splines.Functions25.Linear_Interp(V_XNN1!$K$3:$K$8,V_XNN1!$M$3:$M$8,BT377) -> 0.04104 | BQ377: =IFERROR((BN377 - V_XNN1!$M$16) / (V_XNN1!$M$15- V_XNN1!$M$16) * 100, 0) -> 32.311978 | BR377: 252 | BS377: 249 | BT377: 251.28 | BU377: 0.06 | BV377: 0.050024
A378: 44937 | S378: 0.41844428 | T378: 1.8099045 | U378: 0 | V378: =_xll.SRS1Splines.Functions25.Linear_Interp(V_NK3!$P$8:$P$32,V_NK3!$R$8:$R$32,AC378) -> 451.35772 | W378: =(V378/V_NK3!$R$28)*100 -> 83.253731 | X378: =V378-V_NK3!$R$8 -> 394.77907 | Y378: =IFERROR((V378 - V_NK3!$V$10) / (V_NK3!$V$9- V_NK3!$V$10) * 100, 0) -> 81.302449 | Z378: 541.8 | AA378: 521 | AB378: 537.86 | AC378: 538.52 | AD378: 0.43193548 | AE378: 0.44689 | AH378: 1.7670007 | AI378: 2.1803236 | AJ378: 0 | AK378: =_xll.SRS1Splines.Functions25.Linear_Interp(V_NK2!$R$10:$R$21,V_NK2!$T$10:$T$21,AR378) -> 67.555657 | AL378: =(AK378/V_NK2!$T$18)*100 -> 94.615766 | AM378: =AK378-V_NK2!$T$11 -> 26.735657 | AN378: =IFERROR((AK378 - V_NK2!$X$12) / (V_NK2!$X$11- V_NK2!$X$12) * 100, 0) -> 87.428571 | AO378: 427 | AP378: 420 | AQ378: 427 | AR378: 426.12 | AS378: 0.52806452 | AT378: 0.532172 | BK378: 0.38115926 | BL378: 0.38115926 | BM378: =BK378-BL378 -> 0 | BN378: =_xll.SRS1Splines.Functions25.Linear_Interp(V_XNN1!$K$3:$K$8,V_XNN1!$L$3:$L$8,BT378) -> 0.2064 | BO378: =(BN378/V_XNN1!$L$7)*100 -> 98.285714 | BP378: =_xll.SRS1Splines.Functions25.Linear_Interp(V_XNN1!$K$3:$K$8,V_XNN1!$M$3:$M$8,BT378) -> 0.0504 | BQ378: =IFERROR((BN378 - V_XNN1!$M$16) / (V_XNN1!$M$15- V_XNN1!$M$16) * 100, 0) -> 61.281337 | BR378: 252 | BS378: 249 | BT378: 251.8 | BU378: 0.06 | BV378: 0.054714
A379: 44938 | S379: 0.72126591 | T379: 1.7648611 | U379: 0 | V379: =_xll.SRS1Splines.Functions25.Linear_Interp(V_NK3!$P$8:$P$32,V_NK3!$R$8:$R$32,AC379) -> 450.31413 | W379: =(V379/V_NK3!$R$28)*100 -> 83.061238 | X379: =V379-V_NK3!$R$8 -> 393.73547 | Y379: =IFERROR((V379 - V_NK3!$V$10) / (V_NK3!$V$9- V_NK3!$V$10) * 100, 0) -> 81.087526 | Z379: 541.8 | AA379: 521 | AB379: 537.86 | AC379: 538.49 | AD379: 0.43193548 | AE379: 0.43576817 | AH379: 1.8263927 | AI379: 2.1803236 | AJ379: 0 | AK379: =_xll.SRS1Splines.Functions25.Linear_Interp(V_NK2!$R$10:$R$21,V_NK2!$T$10:$T$21,AR379) -> 67.249857 | AL379: =(AK379/V_NK2!$T$18)*100 -> 94.187475 | AM379: =AK379-V_NK2!$T$11 -> 26.429857 | AN379: =IFERROR((AK379 - V_NK2!$X$12) / (V_NK2!$X$11- V_NK2!$X$12) * 100, 0) -> 86.428571 | AO379: 427 | AP379: 420 | AQ379: 427 | AR379: 426.05 | AS379: 0.52806452 | AT379: 0.533118 | BK379: 0.44995011 | BL379: 0.44966677 | BM379: =BK379-BL379 -> 0.00028333333 | BN379: =_xll.SRS1Splines.Functions25.Linear_Interp(V_XNN1!$K$3:$K$8,V_XNN1!$L$3:$L$8,BT379) -> 0.20478 | BO379: =(BN379/V_XNN1!$L$7)*100 -> 97.514286 | BP379: =_xll.SRS1Splines.Functions25.Linear_Interp(V_XNN1!$K$3:$K$8,V_XNN1!$M$3:$M$8,BT379) -> 0.04878 | BQ379: =IFERROR((BN379 - V_XNN1!$M$16) / (V_XNN1!$M$15- V_XNN1!$M$16) * 100, 0) -> 56.267409 | BR379: 252 | BS379: 249 | BT379: 251.71 | BU379: 0.06 | BV379: 0.064548
... A398: 44957 | S398: 0.4137815 | T398: 1.4237538 | U398: 0 | V398: =_xll.SRS1Splines.Functions25.Linear_Interp(V_NK3!$P$8:$P$32,V_NK3!$R$8:$R$32,AC398) -> 424.51564 | W398: =(V398/V_NK3!$R$28)*100 -> 78.302663 | X398: =V398-V_NK3!$R$8 -> 367.93699 | Y398: =IFERROR((V398 - V_NK3!$V$10) / (V_NK3!$V$9- V_NK3!$V$10) * 100, 0) -> 75.774479 | Z398: 541.8 | AA398: 521 | AB398: 537.86 | AC398: 537.74 | AD398: 0.43193548 | AE398: 0.335791 | AH398: 1.4179264 | AI398: 2.4271527 | AJ398: 0 | AK398: =_xll.SRS1Splines.Functions25.Linear_Interp(V_NK2!$R$10:$R$21,V_NK2!$T$10:$T$21,AR398) -> 40.82 | AL398: =(AK398/V_NK2!$T$18)*100 -> 57.170868 | AM398: =AK398-V_NK2!$T$11 -> 0 | AN398: =IFERROR((AK398 - V_NK2!$X$12) / (V_NK2!$X$11- V_NK2!$X$12) * 100, 0) -> 0 | AO398: 427 | AP398: 420 | AQ398: 427 | AR398: 420 | AS398: 0.52806452 | AT398: 0.591798 | BK398: 0.35967777 | BL398: 0 | BM398: =BK398-BL398 -> 0.35967777 | BN398: =_xll.SRS1Splines.Functions25.Linear_Interp(V_XNN1!$K$3:$K$8,V_XNN1!$L$3:$L$8,BT398) -> 0.210891 | BO398: =(BN398/V_XNN1!$L$7)*100 -> 100.42429 | BP398: =_xll.SRS1Splines.Functions25.Linear_Interp(V_XNN1!$K$3:$K$8,V_XNN1!$M$3:$M$8,BT398) -> 0.054891 | BQ398: =IFERROR((BN398 - V_XNN1!$M$16) / (V_XNN1!$M$15- V_XNN1!$M$16) * 100, 0) -> 75.181058 | BR398: 252 | BS398: 249 | BT398: 252.05 | BU398: 0.06 | BV398: 0
A399: 44958 | S399: 0.67802129 | T399: 0.0047064 | U399: 0 | V399: =_xll.SRS1Splines.Functions25.Linear_Interp(V_NK3!$P$8:$P$32,V_NK3!$R$8:$R$32,AC399) -> 425.18896 | W399: =(V399/V_NK3!$R$28)*100 -> 78.426857 | X399: =V399-V_NK3!$R$8 -> 368.61031 | Y399: =IFERROR((V399 - V_NK3!$V$10) / (V_NK3!$V$9- V_NK3!$V$10) * 100, 0) -> 75.913145 | Z399: 541.8 | AA399: 521 | AB399: 538.09 | AC399: 537.76 | AD399: 0 | AE399: 0.00111 | AH399: 0.22798279 | AI399: 0 | AJ399: 0 | AK399: =_xll.SRS1Splines.Functions25.Linear_Interp(V_NK2!$R$10:$R$21,V_NK2!$T$10:$T$21,AR399) -> 40.863686 | AL399: =(AK399/V_NK2!$T$18)*100 -> 57.232053 | AM399: =AK399-V_NK2!$T$11 -> 0.043685714 | AN399: =IFERROR((AK399 - V_NK2!$X$12) / (V_NK2!$X$11- V_NK2!$X$12) * 100, 0) -> 0.14285714 | AO399: 427 | AP399: 420 | AQ399: 427 | AR399: 420.01 | AS399: 0 | AT399: 0 | BK399: 0.1728 | BM399: =BK399-BL399 -> 0.1728 | BN399: =_xll.SRS1Splines.Functions25.Linear_Interp(V_XNN1!$K$3:$K$8,V_XNN1!$L$3:$L$8,BT399) -> 0.210891 | BO399: =(BN399/V_XNN1!$L$7)*100 -> 100.42429 | BP399: =_xll.SRS1Splines.Functions25.Linear_Interp(V_XNN1!$K$3:$K$8,V_XNN1!$M$3:$M$8,BT399) -> 0.054891 | BQ399: =IFERROR((BN399 - V_XNN1!$M$16) / (V_XNN1!$M$15- V_XNN1!$M$16) * 100, 0) -> 75.181058 | BR399: 252 | BS399: 249 | BT399: 252.05
A400: 44959 | S400: 0.33665745 | T400: 0 | U400: 0 | V400: =_xll.SRS1Splines.Functions25.Linear_Interp(V_NK3!$P$8:$P$32,V_NK3!$R$8:$R$32,AC400) -> 425.52562 | W400: =(V400/V_NK3!$R$28)*100 -> 78.488954 | X400: =V400-V_NK3!$R$8 -> 368.94696 | Y400: =IFERROR((V400 - V_NK3!$V$10) / (V_NK3!$V$9- V_NK3!$V$10) * 100, 0) -> 75.982477 | Z400: 541.8 | AA400: 521 | AB400: 538.09 | AC400: 537.77 | AD400: 0 | AE400: 0 | AH400: 0.11109696 | AI400: 0 | AJ400: 0 | AK400: =_xll.SRS1Splines.Functions25.Linear_Interp(V_NK2!$R$10:$R$21,V_NK2!$T$10:$T$21,AR400) -> 40.951057 | AL400: =(AK400/V_NK2!$T$18)*100 -> 57.354422 | AM400: =AK400-V_NK2!$T$11 -> 0.13105714 | AN400: =IFERROR((AK400 - V_NK2!$X$12) / (V_NK2!$X$11- V_NK2!$X$12) * 100, 0) -> 0.42857143 | AO400: 427 | AP400: 420 | AQ400: 420.46 | AR400: 420.03 | AS400: 0 | AT400: 0 | BK400: 0.16416 | BM400: =BK400-BL400 -> 0.16416 | BN400: =_xll.SRS1Splines.Functions25.Linear_Interp(V_XNN1!$K$3:$K$8,V_XNN1!$L$3:$L$8,BT400) -> 0.210891 | BO400: =(BN400/V_XNN1!$L$7)*100 -> 100.42429 | BP400: =_xll.SRS1Splines.Functions25.Linear_Interp(V_XNN1!$K$3:$K$8,V_XNN1!$M$3:$M$8,BT400) -> 0.054891 | BQ400: =IFERROR((BN400 - V_XNN1!$M$16) / (V_XNN1!$M$15- V_XNN1!$M$16) * 100, 0) -> 75.181058 | BR400: 252 | BS400: 249 | BT400: 252.05
A401: 44960 | S401: 0.33665745 | T401: 0 | U401: 0 | V401: =_xll.SRS1Splines.Functions25.Linear_Interp(V_NK3!$P$8:$P$32,V_NK3!$R$8:$R$32,AC401) -> 425.86227 | W401: =(V401/V_NK3!$R$28)*100 -> 78.551051 | X401: =V401-V_NK3!$R$8 -> 369.28362 | Y401: =IFERROR((V401 - V_NK3!$V$10) / (V_NK3!$V$9- V_NK3!$V$10) * 100, 0) -> 76.05181 | Z401: 541.8 | AA401: 521 | AB401: 538.09 | AC401: 537.78 | AD401: 0 | AE401: 0 | AH401: 0.11109696 | AI401: 0 | AJ401: 0 | AK401: =_xll.SRS1Splines.Functions25.Linear_Interp(V_NK2!$R$10:$R$21,V_NK2!$T$10:$T$21,AR401) -> 41.082114 | AL401: =(AK401/V_NK2!$T$18)*100 -> 57.537975 | AM401: =AK401-V_NK2!$T$11 -> 0.26211429 | AN401: =IFERROR((AK401 - V_NK2!$X$12) / (V_NK2!$X$11- V_NK2!$X$12) * 100, 0) -> 0.85714286 | AO401: 427 | AP401: 420 | AQ401: 420.46 | AR401: 420.06 | AS401: 0 | AT401: 0 | BK401: 0.15552 | BM401: =BK401-BL401 -> 0.15552 | BN401: =_xll.SRS1Splines.Functions25.Linear_Interp(V_XNN1!$K$3:$K$8,V_XNN1!$L$3:$L$8,BT401) -> 0.210891 | BO401: =(BN401/V_XNN1!$L$7)*100 -> 100.42429 | BP401: =_xll.SRS1Splines.Functions25.Linear_Interp(V_XNN1!$K$3:$K$8,V_XNN1!$M$3:$M$8,BT401) -> 0.054891 | BQ401: =IFERROR((BN401 - V_XNN1!$M$16) / (V_XNN1!$M$15- V_XNN1!$M$16) * 100, 0) -> 75.181058 | BR401: 252 | BS401: 249 | BT401: 252.05
A402: 44961 | S402: 0.33665745 | T402: 0 | U402: 0 | V402: =_xll.SRS1Splines.Functions25.Linear_Interp(V_NK3!$P$8:$P$32,V_NK3!$R$8:$R$32,AC402) -> 426.19893 | W402: =(V402/V_NK3!$R$28)*100 -> 78.613148 | X402: =V402-V_NK3!$R$8 -> 369.62028 | Y402: =IFERROR((V402 - V_NK3!$V$10) / (V_NK3!$V$9- V_NK3!$V$10) * 100, 0) -> 76.121143 | Z402: 541.8 | AA402: 521 | AB402: 538.09 | AC402: 537.79 | AD402: 0 | AE402: 0 | AH402: 0.11109696 | AI402: 0 | AJ402: 0 | AK402: =_xll.SRS1Splines.Functions25.Linear_Interp(V_NK2!$R$10:$R$21,V_NK2!$T$10:$T$21,AR402) -> 41.169486 | AL402: =(AK402/V_NK2!$T$18)*100 -> 57.660344 | AM402: =AK402-V_NK2!$T$11 -> 0.34948571 | AN402: =IFERROR((AK402 - V_NK2!$X$12) / (V_NK2!$X$11- V_NK2!$X$12) * 100, 0) -> 1.1428571 | AO402: 427 | AP402: 420 | AQ402: 420.46 | AR402: 420.08 | AS402: 0 | AT402: 0 | BK402: 0.144288 | BM402: =BK402-BL402 -> 0.144288 | BN402: =_xll.SRS1Splines.Functions25.Linear_Interp(V_XNN1!$K$3:$K$8,V_XNN1!$L$3:$L$8,BT402) -> 0.210891 | BO402: =(BN402/V_XNN1!$L$7)*100 -> 100.42429 | BP402: =_xll.SRS1Splines.Functions25.Linear_Interp(V_XNN1!$K$3:$K$8,V_XNN1!$M$3:$M$8,BT402) -> 0.054891 | BQ402: =IFERROR((BN402 - V_XNN1!$M$16) / (V_XNN1!$M$15- V_XNN1!$M$16) * 100, 0) -> 75.181058 | BR402: 252 | BS402: 249 | BT402: 252.05
A403: 44962 | S403: 0.33665745 | T403: 0 | U403: 0 | V403: =_xll.SRS1Splines.Functions25.Linear_Interp(V_NK3!$P$8:$P$32,V_NK3!$R$8:$R$32,AC403) -> 426.53559 | W403: =(V403/V_NK3!$R$28)*100 -> 78.675245 | X403: =V403-V_NK3!$R$8 -> 369.95694 | Y403: =IFERROR((V403 - V_NK3!$V$10) / (V_NK3!$V$9- V_NK3!$V$10) * 100, 0) -> 76.190475 | Z403: 541.8 | AA403: 521 | AB403: 538.09 | AC403: 537.8 | AD403: 0 | AE403: 0 | AH403: 0.11109696 | AI403: 0 | AJ403: 0 | AK403: =_xll.SRS1Splines.Functions25.Linear_Interp(V_NK2!$R$10:$R$21,V_NK2!$T$10:$T$21,AR403) -> 41.256857 | AL403: =(AK403/V_NK2!$T$18)*100 -> 57.782713 | AM403: =AK403-V_NK2!$T$11 -> 0.43685714 | AN403: =IFERROR((AK403 - V_NK2!$X$12) / (V_NK2!$X$11- V_NK2!$X$12) * 100, 0) -> 1.4285714 | AO403: 427 | AP403: 420 | AQ403: 420.46 | AR403: 420.1 | AS403: 0 | AT403: 0 | BK403: 0.119232 | BM403: =BK403-BL403 -> 0.119232 | BN403: =_xll.SRS1Splines.Functions25.Linear_Interp(V_XNN1!$K$3:$K$8,V_XNN1!$L$3:$L$8,BT403) -> 0.210891 | BO403: =(BN403/V_XNN1!$L$7)*100 -> 100.42429 | BP403: =_xll.SRS1Splines.Functions25.Linear_Interp(V_XNN1!$K$3:$K$8,V_XNN1!$M$3:$M$8,BT403) -> 0.054891 | BQ403: =IFERROR((BN403 - V_XNN1!$M$16) / (V_XNN1!$M$15- V_XNN1!$M$16) * 100, 0) -> 75.181058 | BR403: 252 | BS403: 249 | BT403: 252.05
A404: 44963 | S404: 0.33665745 | T404: 0 | U404: 0 | V404: =_xll.SRS1Splines.Functions25.Linear_Interp(V_NK3!$P$8:$P$32,V_NK3!$R$8:$R$32,AC404) -> 426.87225 | W404: =(V404/V_NK3!$R$28)*100 -> 78.737342 | X404: =V404-V_NK3!$R$8 -> 370.29359 | Y404: =IFERROR((V404 - V_NK3!$V$10) / (V_NK3!$V$9- V_NK3!$V$10) * 100, 0) -> 76.259808 | Z404: 541.8 | AA404: 521 | AB404: 538.09 | AC404: 537.81 | AD404: 0 | AE404: 0 | AH404: 0.11109696 | AI404: 0 | AJ404: 0 | AK404: =_xll.SRS1Splines.Functions25.Linear_Interp(V_NK2!$R$10:$R$21,V_NK2!$T$10:$T$21,AR404) -> 41.344229 | AL404: =(AK404/V_NK2!$T$18)*100 -> 57.905082 | AM404: =AK404-V_NK2!$T$11 -> 0.52422857 | AN404: =IFERROR((AK404 - V_NK2!$X$12) / (V_NK2!$X$11- V_NK2!$X$12) * 100, 0) -> 1.7142857 | AO404: 427 | AP404: 420 | AQ404: 420.46 | AR404: 420.12 | AS404: 0 | AT404: 0 | BK404: 0.1728 | BM404: =BK404-BL404 -> 0.1728 | BN404: =_xll.SRS1Splines.Functions25.Linear_Interp(V_XNN1!$K$3:$K$8,V_XNN1!$L$3:$L$8,BT404) -> 0.210891 | BO404: =(BN404/V_XNN1!$L$7)*100 -> 100.42429 | BP404: =_xll.SRS1Splines.Functions25.Linear_Interp(V_XNN1!$K$3:$K$8,V_XNN1!$M$3:$M$8,BT404) -> 0.054891 | BQ404: =IFERROR((BN404 - V_XNN1!$M$16) / (V_XNN1!$M$15- V_XNN1!$M$16) * 100, 0) -> 75.181058 | BR404: 252 | BS404: 249 | BT404: 252.05
A405: 44964 | S405: 0.33665745 | T405: 0 | U405: 0 | V405: =_xll.SRS1Splines.Functions25.Linear_Interp(V_NK3!$P$8:$P$32,V_NK3!$R$8:$R$32,AC405) -> 427.2089 | W405: =(V405/V_NK3!$R$28)*100 -> 78.799439 | X405: =V405-V_NK3!$R$8 -> 370.63025 | Y405: =IFERROR((V405 - V_NK3!$V$10) / (V_NK3!$V$9- V_NK3!$V$10) * 100, 0) -> 76.32914 | Z405: 541.8 | AA405: 521 | AB405: 538.09 | AC405: 537.82 | AD405: 0 | AE405: 0 | AH405: 0.11109696 | AI405: 0 | AJ405: 0 | AK405: =_xll.SRS1Splines.Functions25.Linear_Interp(V_NK2!$R$10:$R$21,V_NK2!$T$10:$T$21,AR405) -> 41.475286 | AL405: =(AK405/V_NK2!$T$18)*100 -> 58.088635 | AM405: =AK405-V_NK2!$T$11 -> 0.65528571 | AN405: =IFERROR((AK405 - V_NK2!$X$12) / (V_NK2!$X$11- V_NK2!$X$12) * 100, 0) -> 2.1428571 | AO405: 427 | AP405: 420 | AQ405: 420.46 | AR405: 420.15 | AS405: 0 | AT405: 0 | BK405: 0.16416 | BM405: =BK405-BL405 -> 0.16416 | BN405: =_xll.SRS1Splines.Functions25.Linear_Interp(V_XNN1!$K$3:$K$8,V_XNN1!$L$3:$L$8,BT405) -> 0.210891 | BO405: =(BN405/V_XNN1!$L$7)*100 -> 100.42429 | BP405: =_xll.SRS1Splines.Functions25.Linear_Interp(V_XNN1!$K$3:$K$8,V_XNN1!$M$3:$M$8,BT405) -> 0.054891 | BQ405: =IFERROR((BN405 - V_XNN1!$M$16) / (V_XNN1!$M$15- V_XNN1!$M$16) * 100, 0) -> 75.181058 | BR405: 252 | BS405: 249 | BT405: 252.05
A406: 44965 | S406: 0.33665745 | T406: 0 | U406: 0 | V406: =_xll.SRS1Splines.Functions25.Linear_Interp(V_NK3!$P$8:$P$32,V_NK3!$R$8:$R$32,AC406) -> 427.54556 | W406: =(V406/V_NK3!$R$28)*100 -> 78.861536 | X406: =V406-V_NK3!$R$8 -> 370.96691 | Y406: =IFERROR((V406 - V_NK3!$V$10) / (V_NK3!$V$9- V_NK3!$V$10) * 100, 0) -> 76.398473 | Z406: 541.8 | AA406: 521 | AB406: 538.09 | AC406: 537.83 | AD406: 0 | AE406: 0 | AH406: 0.11109696 | AI406: 0 | AJ406: 0 | AK406: =_xll.SRS1Splines.Functions25.Linear_Interp(V_NK2!$R$10:$R$21,V_NK2!$T$10:$T$21,AR406) -> 41.562657 | AL406: =(AK406/V_NK2!$T$18)*100 -> 58.211004 | AM406: =AK406-V_NK2!$T$11 -> 0.74265714 | AN406: =IFERROR((AK406 - V_NK2!$X$12) / (V_NK2!$X$11- V_NK2!$X$12) * 100, 0) -> 2.4285714 | AO406: 427 | AP406: 420 | AQ406: 420.46 | AR406: 420.17 | AS406: 0 | AT406: 0 | BK406: 0.119232 | BM406: =BK406-BL406 -> 0.119232 | BN406: =_xll.SRS1Splines.Functions25.Linear_Interp(V_XNN1!$K$3:$K$8,V_XNN1!$L$3:$L$8,BT406) -> 0.210891 | BO406: =(BN406/V_XNN1!$L$7)*100 -> 100.42429 | BP406: =_xll.SRS1Splines.Functions25.Linear_Interp(V_XNN1!$K$3:$K$8,V_XNN1!$M$3:$M$8,BT406) -> 0.054891 | BQ406: =IFERROR((BN406 - V_XNN1!$M$16) / (V_XNN1!$M$15- V_XNN1!$M$16) * 100, 0) -> 75.181058 | BR406: 252 | BS406: 249 | BT406: 252.05
A407: 44966 | S407: 0.67331489 | T407: 0 | U407: 0 | V407: =_xll.SRS1Splines.Functions25.Linear_Interp(V_NK3!$P$8:$P$32,V_NK3!$R$8:$R$32,AC407) -> 428.21888 | W407: =(V407/V_NK3!$R$28)*100 -> 78.98573 | X407: =V407-V_NK3!$R$8 -> 371.64022 | Y407: =IFERROR((V407 - V_NK3!$V$10) / (V_NK3!$V$9- V_NK3!$V$10) * 100, 0) -> 76.537138 | Z407: 541.8 | AA407: 521 | AB407: 538.09 | AC407: 537.85 | AD407: 0 | AE407: 0 | AH407: 0.22219391 | AI407: 0 | AJ407: 0 | AK407: =_xll.SRS1Splines.Functions25.Linear_Interp(V_NK2!$R$10:$R$21,V_NK2!$T$10:$T$21,AR407) -> 41.606343 | AL407: =(AK407/V_NK2!$T$18)*100 -> 58.272189 | AM407: =AK407-V_NK2!$T$11 -> 0.78634286 | AN407: =IFERROR((AK407 - V_NK2!$X$12) / (V_NK2!$X$11- V_NK2!$X$12) * 100, 0) -> 2.5714286 | AO407: 427 | AP407: 420 | AQ407: 420.46 | AR407: 420.18 | AS407: 0 | AT407: 0 | BK407: 0.1728 | BM407: =BK407-BL407 -> 0.1728 | BN407: =_xll.SRS1Splines.Functions25.Linear_Interp(V_XNN1!$K$3:$K$8,V_XNN1!$L$3:$L$8,BT407) -> 0.210891 | BO407: =(BN407/V_XNN1!$L$7)*100 -> 100.42429 | BP407: =_xll.SRS1Splines.Functions25.Linear_Interp(V_XNN1!$K$3:$K$8,V_XNN1!$M$3:$M$8,BT407) -> 0.054891 | BQ407: =IFERROR((BN407 - V_XNN1!$M$16) / (V_XNN1!$M$15- V_XNN1!$M$16) * 100, 0) -> 75.181058 | BR407: 252 | BS407: 249 | BT407: 252.05
A408: 44967 | S408: 0.33665745 | T408: 0 | U408: 0 | V408: =_xll.SRS1Splines.Functions25.Linear_Interp(V_NK3!$P$8:$P$32,V_NK3!$R$8:$R$32,AC408) -> 428.55553 | W408: =(V408/V_NK3!$R$28)*100 -> 79.047827 | X408: =V408-V_NK3!$R$8 -> 371.97688 | Y408: =IFERROR((V408 - V_NK3!$V$10) / (V_NK3!$V$9- V_NK3!$V$10) * 100, 0) -> 76.606471 | Z408: 541.8 | AA408: 521 | AB408: 538.09 | AC408: 537.86 | AD408: 0 | AE408: 0 | AH408: 0.11109696 | AI408: 0 | AJ408: 0 | AK408: =_xll.SRS1Splines.Functions25.Linear_Interp(V_NK2!$R$10:$R$21,V_NK2!$T$10:$T$21,AR408) -> 41.693714 | AL408: =(AK408/V_NK2!$T$18)*100 -> 58.394558 | AM408: =AK408-V_NK2!$T$11 -> 0.87371429 | AN408: =IFERROR((AK408 - V_NK2!$X$12) / (V_NK2!$X$11- V_NK2!$X$12) * 100, 0) -> 2.8571429 | AO408: 427 | AP408: 420 | AQ408: 420.46 | AR408: 420.2 | AS408: 0 | AT408: 0 | BK408: 0.16416 | BM408: =BK408-BL408 -> 0.16416 | BN408: =_xll.SRS1Splines.Functions25.Linear_Interp(V_XNN1!$K$3:$K$8,V_XNN1!$L$3:$L$8,BT408) -> 0.210891 | BO408: =(BN408/V_XNN1!$L$7)*100 -> 100.42429 | BP408: =_xll.SRS1Splines.Functions25.Linear_Interp(V_XNN1!$K$3:$K$8,V_XNN1!$M$3:$M$8,BT408) -> 0.054891 | BQ408: =IFERROR((BN408 - V_XNN1!$M$16) / (V_XNN1!$M$15- V_XNN1!$M$16) * 100, 0) -> 75.181058 | BR408: 252 | BS408: 249 | BT408: 252.05
A409: 44968 | S409: 0.33665745 | T409: 0 | U409: 0 | V409: =_xll.SRS1Splines.Functions25.Linear_Interp(V_NK3!$P$8:$P$32,V_NK3!$R$8:$R$32,AC409) -> 428.89219 | W409: =(V409/V_NK3!$R$28)*100 -> 79.109924 | X409: =V409-V_NK3!$R$8 -> 372.31354 | Y409: =IFERROR((V409 - V_NK3!$V$10) / (V_NK3!$V$9- V_NK3!$V$10) * 100, 0) -> 76.675804 | Z409: 541.8 | AA409: 521 | AB409: 538.09 | AC409: 537.87 | AD409: 0 | AE409: 0 | AH409: 0.11109696 | AI409: 0 | AJ409: 0 | AK409: =_xll.SRS1Splines.Functions25.Linear_Interp(V_NK2!$R$10:$R$21,V_NK2!$T$10:$T$21,AR409) -> 41.781086 | AL409: =(AK409/V_NK2!$T$18)*100 -> 58.516927 | AM409: =AK409-V_NK2!$T$11 -> 0.96108571 | AN409: =IFERROR((AK409 - V_NK2!$X$12) / (V_NK2!$X$11- V_NK2!$X$12) * 100, 0) -> 3.1428571 | AO409: 427 | AP409: 420 | AQ409: 420.46 | AR409: 420.22 | AS409: 0 | AT409: 0 | BK409: 0.1728 | BM409: =BK409-BL409 -> 0.1728 | BN409: =_xll.SRS1Splines.Functions25.Linear_Interp(V_XNN1!$K$3:$K$8,V_XNN1!$L$3:$L$8,BT409) -> 0.210891 | BO409: =(BN409/V_XNN1!$L$7)*100 -> 100.42429 | BP409: =_xll.SRS1Splines.Functions25.Linear_Interp(V_XNN1!$K$3:$K$8,V_XNN1!$M$3:$M$8,BT409) -> 0.054891 | BQ409: =IFERROR((BN409 - V_XNN1!$M$16) / (V_XNN1!$M$15- V_XNN1!$M$16) * 100, 0) -> 75.181058 | BR409: 252 | BS409: 249 | BT409: 252.05
...

Sheet V_NEM
A1: Main Dam | D1: 1000000 | E1: DIV Dam | I1: Main Dam | J1: DIV Dam
A2: Level | B2: Full Mm3 | C2: Active volume | E2: Elevation | F2: Full Mm3 | G2: Active Volume | H2: Level | I2: Full Volumne m3 | J2: Full Volume m3 | M2: ຄ່າໄຟ M$/GWh
A3: 775 | B3: 0.00042447 | C3: 0 | E3: 772 | F3: 0.006133825 | G3: 0 | H3: 772 | I3: 424.47 | J3: 6133.825 | M3: =(0.9*0.07316+0.1*0.0365) -> 0.069494
A4: 775.01 | B4: 0.0004412711 | C4: 0 | E4: 772.01 | F4: 0.0062471847 | G4: 0 | H4: 772.01 | I4: 441.2711 | J4: 6247.1847
A5: 775.02 | B5: 0.0004580722 | C5: 0 | E5: 772.02 | F5: 0.0063605443 | G5: 0 | H5: 772.02 | I5: 458.0722 | J5: 6360.5443
A6: 775.03 | B6: 0.0004748733 | C6: 0 | E6: 772.03 | F6: 0.006473904 | G6: 0 | H6: 772.03 | I6: 474.8733 | J6: 6473.904
A7: 775.04 | B7: 0.0004916744 | C7: 0 | E7: 772.04 | F7: 0.0065872636 | G7: 0 | H7: 772.04 | I7: 491.6744 | J7: 6587.2636
A8: 775.05 | B8: 0.0005084755 | C8: 0 | E8: 772.05 | F8: 0.0067006233 | G8: 0 | H8: 772.05 | I8: 508.4755 | J8: 6700.6233
A9: 775.06 | B9: 0.0005252766 | C9: 0 | E9: 772.06 | F9: 0.0068139829 | G9: 0 | H9: 772.06 | I9: 525.2766 | J9: 6813.9829
A10: 775.07 | B10: 0.0005420777 | C10: 0 | E10: 772.07 | F10: 0.0069273426 | G10: 0 | H10: 772.07 | I10: 542.0777 | J10: 6927.3426
A11: 775.08 | B11: 0.0005588788 | C11: 0 | E11: 772.08 | F11: 0.0070407022 | G11: 0 | H11: 772.08 | I11: 558.8788 | J11: 7040.7022
A12: 775.09 | B12: 0.0005756799 | C12: 0 | E12: 772.09 | F12: 0.0071540619 | G12: 0 | H12: 772.09 | I12: 575.6799 | J12: 7154.0619
A13: 775.1 | B13: 0.000592481 | C13: 0 | E13: 772.1 | F13: 0.0072674215 | G13: 0 | H13: 772.1 | I13: 592.481 | J13: 7267.4215
A14: 775.11 | B14: 0.0006092821 | C14: 0 | E14: 772.11 | F14: 0.0073807812 | G14: 0 | H14: 772.11 | I14: 609.2821 | J14: 7380.7812
A15: 775.12 | B15: 0.0006260832 | C15: 0 | E15: 772.12 | F15: 0.0074941408 | G15: 0 | H15: 772.12 | I15: 626.0832 | J15: 7494.1408
... A683: 781.8 | B683: 0.059305707 | C683: 0 | E683: 778.8 | F683: 0.26510132 | G683: 0 | H683: 778.8 | I683: 59305.707 | J683: 265101.32
A684: 781.81 | B684: 0.059507843 | C684: =B684-$B$683 -> 0.00020213565 | E684: 778.81 | F684: 0.26582906 | G684: =F684-$F$683 -> 0.00072774045 | H684: 778.81 | I684: 59507.843 | J684: 265829.06 | R684: NEM Main Dam Reservoir Water Level and Volume data | AB684: NEM Diversion Dam Reservoir Water Level and Volume data
A685: 781.82 | B685: 0.059709978 | C685: =B685-$B$683 -> 0.0004042713 | E685: 778.82 | F685: 0.2665568 | G685: =F685-$F$683 -> 0.0014554809 | H685: 778.82 | I685: 59709.978 | J685: 266556.8 | R685: MASL | S685: Volume (m3) | V685: NO. | W685: Elevation | X685: Interpolated Volume | Y685: Storage | Z685: Space | AB685: MASL | AC685: Volume (m3) | AF685: NO. | AG685: Elevation | AH685: Interpolated Volume | AI685: Storage | AJ685: Space
A686: 781.83 | B686: 0.059912114 | C686: =B686-$B$683 -> 0.00060640695 | E686: 778.83 | F686: 0.26728454 | G686: =F686-$F$683 -> 0.0021832213 | H686: 778.83 | I686: 59912.114 | J686: 267284.54 | S686: m3 | T686: MCM | W686: MASL | X686: MCM | Y686: % | Z686: m | AC686: m3 | AD686: MCM | AG686: MASL | AH686: MCM | AI686: % | AJ686: m
A687: 781.84 | B687: 0.06011425 | C687: =B687-$B$683 -> 0.0008085426 | E687: 778.84 | F687: 0.26801228 | G687: =F687-$F$683 -> 0.0029109618 | H687: 778.84 | I687: 60114.25 | J687: 268012.28 | R687: 775 | S687: 61097.265 | T687: =S687/1000000 -> 0.061097265 | V687: Input MASL | W687: 784 | X687: =_xll.SRS1Splines.Functions25.Linear_Interp($R$687:$R$703,$T$687:$T$703,W687) -> 0.8552866 | Y687: =IFERROR((X687 - $X$689) / ($X$688- $X$689) * 100, 0) -> 100 | Z687: =W688-W687 -> 0 | AB687: 775 | AC687: 424.47 | AD687: =AC687/1000000 -> 0.00042447 | AF687: Input MASL | AG687: 783 | AH687: =_xll.SRS1Splines.Functions25.Linear_Interp($AB$687:$AB$703,$AD$687:$AD$703,AG687) -> 0.08661698 | AI687: =IFERROR((AH687 - $AH$689) / ($AH$688- $AH$689) * 100, 0) -> 46.040272 | AJ687: =AG688-AG687 -> 1
A688: 781.85 | B688: 0.060316385 | C688: =B688-$B$683 -> 0.0010106782 | E688: 778.85 | F688: 0.26874002 | G688: =F688-$F$683 -> 0.0036387022 | H688: 778.85 | I688: 60316.385 | J688: 268740.02 | R688: 776 | S688: 99021.175 | T688: =S688/1000000 -> 0.099021175 | V688: FSL | W688: 784 | X688: =_xll.SRS1Splines.Functions25.Linear_Interp($R$687:$R$703,$T$687:$T$703,W688) -> 0.8552866 | Y688: =IFERROR((X688 - $X$689) / ($X$688- $X$689) * 100, 0) -> 100 | AB688: 776 | AC688: 2104.58 | AD688: =AC688/1000000 -> 0.00210458 | AF688: FSL | AG688: 784 | AH688: =_xll.SRS1Splines.Functions25.Linear_Interp($AB$687:$AB$703,$AD$687:$AD$703,AG688) -> 0.113888 | AI688: =IFERROR((AH688 - $AH$689) / ($AH$688- $AH$689) * 100, 0) -> 100
A689: 781.86 | B689: 0.060518521 | C689: =B689-$B$683 -> 0.0012128139 | E689: 778.86 | F689: 0.26946776 | G689: =F689-$F$683 -> 0.0043664427 | H689: 778.86 | I689: 60518.521 | J689: 269467.76 | R689: 777 | S689: 147830.49 | T689: =S689/1000000 -> 0.14783049 | V689: MOL | W689: 782 | X689: =_xll.SRS1Splines.Functions25.Linear_Interp($R$687:$R$703,$T$687:$T$703,W689) -> 0.57613771 | Y689: =IFERROR((X689 - $X$689) / ($X$688- $X$689) * 100, 0) -> 0 | AB689: 777 | AC689: 5290.14 | AD689: =AC689/1000000 -> 0.00529014 | AF689: MOL | AG689: 782 | AH689: =_xll.SRS1Splines.Functions25.Linear_Interp($AB$687:$AB$703,$AD$687:$AD$703,AG689) -> 0.06334842 | AI689: =IFERROR((AH689 - $AH$689) / ($AH$688- $AH$689) * 100, 0) -> 0
A690: 781.87 | B690: 0.060720657 | C690: =B690-$B$683 -> 0.0014149495 | E690: 778.87 | F690: 0.2701955 | G690: =F690-$F$683 -> 0.0050941831 | H690: 778.87 | I690: 60720.657 | J690: 270195.5 | R690: 778 | S690: 206882.08 | T690: =S690/1000000 -> 0.20688208 | AB690: 778 | AC690: 9800.555 | AD690: =AC690/1000000 -> 0.009800555
A691: 781.88 | B691: 0.060922792 | C691: =B691-$B$683 -> 0.0016170852 | E691: 778.88 | F691: 0.27092324 | G691: =F691-$F$683 -> 0.0058219236 | H691: 778.88 | I691: 60922.792 | J691: 270923.24 | R691: 779 | S691: 279656.12 | T691: =S691/1000000 -> 0.27965612 | AB691: 779 | AC691: 16518.765 | AD691: =AC691/1000000 -> 0.016518765
A692: 781.89 | B692: 0.061124928 | C692: =B692-$B$683 -> 0.0018192208 | E692: 778.89 | F692: 0.27165098 | G692: =F692-$F$683 -> 0.006549664 | H692: 778.89 | I692: 61124.928 | J692: 271650.98 | R692: 780 | S692: 364285.99 | T692: =S692/1000000 -> 0.36428599 | AB692: 780 | AC692: 27183.635 | AD692: =AC692/1000000 -> 0.027183635
A693: 781.9 | B693: 0.061327063 | C693: =B693-$B$683 -> 0.0020213565 | E693: 778.9 | F693: 0.27237872 | G693: =F693-$F$683 -> 0.0072774045 | H693: 778.9 | I693: 61327.063 | J693: 272378.72 | R693: 781 | S693: 462315.6 | T693: =S693/1000000 -> 0.4623156 | AB693: 781 | AC693: 43134.855 | AD693: =AC693/1000000 -> 0.043134855
A694: 781.91 | B694: 0.061529199 | C694: =B694-$B$683 -> 0.0022234921 | E694: 778.91 | F694: 0.27310646 | G694: =F694-$F$683 -> 0.0080051449 | H694: 778.91 | I694: 61529.199 | J694: 273106.46 | R694: 782 | S694: 576137.71 | T694: =S694/1000000 -> 0.57613771 | AB694: 782 | AC694: 63348.42 | AD694: =AC694/1000000 -> 0.06334842
A695: 781.92 | B695: 0.061731335 | C695: =B695-$B$683 -> 0.0024256278 | E695: 778.92 | F695: 0.2738342 | G695: =F695-$F$683 -> 0.0087328854 | H695: 778.92 | I695: 61731.335 | J695: 273834.2 | R695: 783 | S695: 706362.85 | T695: =S695/1000000 -> 0.70636285 | AB695: 783 | AC695: 86616.98 | AD695: =AC695/1000000 -> 0.08661698
A696: 781.93 | B696: 0.06193347 | C696: =B696-$B$683 -> 0.0026277634 | E696: 778.93 | F696: 0.27456194 | G696: =F696-$F$683 -> 0.0094606258 | H696: 778.93 | I696: 61933.47 | J696: 274561.94 | R696: 784 | S696: 855286.6 | T696: =S696/1000000 -> 0.8552866 | AB696: 784 | AC696: 113888 | AD696: =AC696/1000000 -> 0.113888
